<robot name = "2_R_robot">
    
  <material name="blue">
    <color rgba="0 0 0.8 1"/>
  </material>
  <material name="black">
    <color rgba="0 0 0 1"/>
  </material>
  <material name="white">
    <color rgba="1 1 1 1"/>
  </material>

  <link name ="fixed_base">
    <visual>
      <geometry>
        <sphere radius="0.1"/>
      </geometry>
      <origin rpy="0 0 0" xyz="0 0 0"/>
      <material name="blue"/>
    </visual>
  </link>
 <link name ="link_1">
    <visual>
      <geometry>
        <cylinder length="0.6" radius="0.05"/>
      </geometry>
      <origin rpy ="0 1.57 0" xyz ="0.3 0 0"/>
      <material name ="black"/>
    </visual>
 </link>
          
       
     
 <link name ="link_2">
    <visual>
      <geometry>
        <cylinder length ="0.6" radius ="0.05"/>
      </geometry>
      <origin rpy ="0 1.57 0" xyz="0.3 0 0"/>
      <material name ="white"/>
    </visual>
 </link>


 <link name="link_3">
    <visual>
      <geometry>
        <sphere radius ="0.1"/>
      </geometry>
      <origin rpy = "0 0 0" xyz = "0 0 0"/>
      <material name ="blue"/>
    </visual>
 </link>

  <joint name = "Revolute_joint_1" type = "revolute">
    <parent link = "fixed_base"/>
    <child link = "link_1"/>
    <origin rpy = "0 0 0.78" xyz = "0 0 0"/>
    <axis xyz = "0 0 1"/>
    <limit lower="-3.14" upper="3.14" effort="5" velocity="0.5"/>
  </joint>

  <joint name = "revolute_joint_2" type = "revolute">
    <parent link = "link_1"/>
    <child link = "link_2"/>
    <origin xyz = "0.6 0 0"/>
    <axis xyz = "0 0 1"/>
    <limit lower="-3.14" upper="3.14" effort="5" velocity="0.5"/>
  </joint>
   
  <joint name = "revolute_joint_3" type = "fixed">
    <parent link = "link_1"/>
    <child link = "link_3"/>
    <origin xyz = "0.6 0 0"/>
    <axis xyz = "0 0 1"/>
  </joint>
</robot>